2025-01-31 02:22:52,676 - INFO - Using data file: data/morphosource_data_complete.json
2025-01-31 02:22:55,099 - INFO - Found 104502 URLs to process
2025-01-31 02:22:55,100 - INFO - Starting with: index=0, processed=0, target=100
2025-01-31 02:22:55,101 - INFO - Processing up to 10 records this batch
2025-01-31 02:22:55,101 - INFO - Total target: 100, Remaining: 100
2025-01-31 02:22:55,101 - INFO - Starting at index 0, processed so far: 0
2025-01-31 02:22:55,102 - INFO - Processing batch from index 0 to 10 (total processed so far: 0)
2025-01-31 02:22:55,212 - INFO - Processing record 0 (URL: https://www.morphosource.org/concern/media/000705639?locale=en)
2025-01-31 02:22:55,213 - INFO - Setting up new Chrome driver
2025-01-31 02:22:55,393 - ERROR - Error on attempt 1 for https://www.morphosource.org/concern/media/000705639?locale=en: Message: Unable to obtain driver for chrome; For documentation on this error, please visit: https://www.selenium.dev/documentation/webdriver/troubleshooting/errors/driver_location
Traceback (most recent call last):
  File "/usr/local/lib/python3.10/site-packages/selenium/webdriver/common/driver_finder.py", line 67, in _binary_paths
    output = SeleniumManager().binary_paths(self._to_args())
  File "/usr/local/lib/python3.10/site-packages/selenium/webdriver/common/selenium_manager.py", line 55, in binary_paths
    return self._run(args)
  File "/usr/local/lib/python3.10/site-packages/selenium/webdriver/common/selenium_manager.py", line 129, in _run
    raise WebDriverException(
selenium.common.exceptions.WebDriverException: Message: Unsuccessful command executed: /usr/local/lib/python3.10/site-packages/selenium/webdriver/common/linux/selenium-manager --browser chrome --browser-path /usr/bin/google-chrome --language-binding python --output json; code: 65
{'code': 65, 'message': 'Browser path does not exist: /usr/bin/google-chrome', 'driver_path': '', 'browser_path': ''}



The above exception was the direct cause of the following exception:

Traceback (most recent call last):
  File "/Users/jt/Documents/GitHub/Parquet-Processor/.github/scripts/test_parquet_processor.py", line 298, in process_url_batch
    driver = setup_driver()
  File "/Users/jt/Documents/GitHub/Parquet-Processor/.github/scripts/test_parquet_processor.py", line 72, in setup_driver
    driver = webdriver.Chrome(options=chrome_options)
  File "/usr/local/lib/python3.10/site-packages/selenium/webdriver/chrome/webdriver.py", line 45, in __init__
    super().__init__(
  File "/usr/local/lib/python3.10/site-packages/selenium/webdriver/chromium/webdriver.py", line 50, in __init__
    if finder.get_browser_path():
  File "/usr/local/lib/python3.10/site-packages/selenium/webdriver/common/driver_finder.py", line 47, in get_browser_path
    return self._binary_paths()["browser_path"]
  File "/usr/local/lib/python3.10/site-packages/selenium/webdriver/common/driver_finder.py", line 78, in _binary_paths
    raise NoSuchDriverException(msg) from err
selenium.common.exceptions.NoSuchDriverException: Message: Unable to obtain driver for chrome; For documentation on this error, please visit: https://www.selenium.dev/documentation/webdriver/troubleshooting/errors/driver_location

2025-01-31 02:22:55,400 - INFO - Retrying https://www.morphosource.org/concern/media/000705639?locale=en after error...
2025-01-31 02:22:56,410 - INFO - Setting up new Chrome driver
2025-01-31 02:22:56,563 - ERROR - Error on attempt 2 for https://www.morphosource.org/concern/media/000705639?locale=en: Message: Unable to obtain driver for chrome; For documentation on this error, please visit: https://www.selenium.dev/documentation/webdriver/troubleshooting/errors/driver_location
Traceback (most recent call last):
  File "/usr/local/lib/python3.10/site-packages/selenium/webdriver/common/driver_finder.py", line 67, in _binary_paths
    output = SeleniumManager().binary_paths(self._to_args())
  File "/usr/local/lib/python3.10/site-packages/selenium/webdriver/common/selenium_manager.py", line 55, in binary_paths
    return self._run(args)
  File "/usr/local/lib/python3.10/site-packages/selenium/webdriver/common/selenium_manager.py", line 129, in _run
    raise WebDriverException(
selenium.common.exceptions.WebDriverException: Message: Unsuccessful command executed: /usr/local/lib/python3.10/site-packages/selenium/webdriver/common/linux/selenium-manager --browser chrome --browser-path /usr/bin/google-chrome --language-binding python --output json; code: 65
{'code': 65, 'message': 'Browser path does not exist: /usr/bin/google-chrome', 'driver_path': '', 'browser_path': ''}



The above exception was the direct cause of the following exception:

Traceback (most recent call last):
  File "/Users/jt/Documents/GitHub/Parquet-Processor/.github/scripts/test_parquet_processor.py", line 298, in process_url_batch
    driver = setup_driver()
  File "/Users/jt/Documents/GitHub/Parquet-Processor/.github/scripts/test_parquet_processor.py", line 72, in setup_driver
    driver = webdriver.Chrome(options=chrome_options)
  File "/usr/local/lib/python3.10/site-packages/selenium/webdriver/chrome/webdriver.py", line 45, in __init__
    super().__init__(
  File "/usr/local/lib/python3.10/site-packages/selenium/webdriver/chromium/webdriver.py", line 50, in __init__
    if finder.get_browser_path():
  File "/usr/local/lib/python3.10/site-packages/selenium/webdriver/common/driver_finder.py", line 47, in get_browser_path
    return self._binary_paths()["browser_path"]
  File "/usr/local/lib/python3.10/site-packages/selenium/webdriver/common/driver_finder.py", line 78, in _binary_paths
    raise NoSuchDriverException(msg) from err
selenium.common.exceptions.NoSuchDriverException: Message: Unable to obtain driver for chrome; For documentation on this error, please visit: https://www.selenium.dev/documentation/webdriver/troubleshooting/errors/driver_location

2025-01-31 02:22:56,568 - INFO - Processing record 0 (URL: https://www.morphosource.org/concern/media/000705613?locale=en)
2025-01-31 02:22:56,568 - INFO - Setting up new Chrome driver
2025-01-31 02:22:56,708 - ERROR - Error on attempt 1 for https://www.morphosource.org/concern/media/000705613?locale=en: Message: Unable to obtain driver for chrome; For documentation on this error, please visit: https://www.selenium.dev/documentation/webdriver/troubleshooting/errors/driver_location
Traceback (most recent call last):
  File "/usr/local/lib/python3.10/site-packages/selenium/webdriver/common/driver_finder.py", line 67, in _binary_paths
    output = SeleniumManager().binary_paths(self._to_args())
  File "/usr/local/lib/python3.10/site-packages/selenium/webdriver/common/selenium_manager.py", line 55, in binary_paths
    return self._run(args)
  File "/usr/local/lib/python3.10/site-packages/selenium/webdriver/common/selenium_manager.py", line 129, in _run
    raise WebDriverException(
selenium.common.exceptions.WebDriverException: Message: Unsuccessful command executed: /usr/local/lib/python3.10/site-packages/selenium/webdriver/common/linux/selenium-manager --browser chrome --browser-path /usr/bin/google-chrome --language-binding python --output json; code: 65
{'code': 65, 'message': 'Browser path does not exist: /usr/bin/google-chrome', 'driver_path': '', 'browser_path': ''}



The above exception was the direct cause of the following exception:

Traceback (most recent call last):
  File "/Users/jt/Documents/GitHub/Parquet-Processor/.github/scripts/test_parquet_processor.py", line 298, in process_url_batch
    driver = setup_driver()
  File "/Users/jt/Documents/GitHub/Parquet-Processor/.github/scripts/test_parquet_processor.py", line 72, in setup_driver
    driver = webdriver.Chrome(options=chrome_options)
  File "/usr/local/lib/python3.10/site-packages/selenium/webdriver/chrome/webdriver.py", line 45, in __init__
    super().__init__(
  File "/usr/local/lib/python3.10/site-packages/selenium/webdriver/chromium/webdriver.py", line 50, in __init__
    if finder.get_browser_path():
  File "/usr/local/lib/python3.10/site-packages/selenium/webdriver/common/driver_finder.py", line 47, in get_browser_path
    return self._binary_paths()["browser_path"]
  File "/usr/local/lib/python3.10/site-packages/selenium/webdriver/common/driver_finder.py", line 78, in _binary_paths
    raise NoSuchDriverException(msg) from err
selenium.common.exceptions.NoSuchDriverException: Message: Unable to obtain driver for chrome; For documentation on this error, please visit: https://www.selenium.dev/documentation/webdriver/troubleshooting/errors/driver_location

2025-01-31 02:22:56,710 - INFO - Retrying https://www.morphosource.org/concern/media/000705613?locale=en after error...
2025-01-31 02:22:57,716 - INFO - Setting up new Chrome driver
2025-01-31 02:22:57,860 - ERROR - Error on attempt 2 for https://www.morphosource.org/concern/media/000705613?locale=en: Message: Unable to obtain driver for chrome; For documentation on this error, please visit: https://www.selenium.dev/documentation/webdriver/troubleshooting/errors/driver_location
Traceback (most recent call last):
  File "/usr/local/lib/python3.10/site-packages/selenium/webdriver/common/driver_finder.py", line 67, in _binary_paths
    output = SeleniumManager().binary_paths(self._to_args())
  File "/usr/local/lib/python3.10/site-packages/selenium/webdriver/common/selenium_manager.py", line 55, in binary_paths
    return self._run(args)
  File "/usr/local/lib/python3.10/site-packages/selenium/webdriver/common/selenium_manager.py", line 129, in _run
    raise WebDriverException(
selenium.common.exceptions.WebDriverException: Message: Unsuccessful command executed: /usr/local/lib/python3.10/site-packages/selenium/webdriver/common/linux/selenium-manager --browser chrome --browser-path /usr/bin/google-chrome --language-binding python --output json; code: 65
{'code': 65, 'message': 'Browser path does not exist: /usr/bin/google-chrome', 'driver_path': '', 'browser_path': ''}



The above exception was the direct cause of the following exception:

Traceback (most recent call last):
  File "/Users/jt/Documents/GitHub/Parquet-Processor/.github/scripts/test_parquet_processor.py", line 298, in process_url_batch
    driver = setup_driver()
  File "/Users/jt/Documents/GitHub/Parquet-Processor/.github/scripts/test_parquet_processor.py", line 72, in setup_driver
    driver = webdriver.Chrome(options=chrome_options)
  File "/usr/local/lib/python3.10/site-packages/selenium/webdriver/chrome/webdriver.py", line 45, in __init__
    super().__init__(
  File "/usr/local/lib/python3.10/site-packages/selenium/webdriver/chromium/webdriver.py", line 50, in __init__
    if finder.get_browser_path():
  File "/usr/local/lib/python3.10/site-packages/selenium/webdriver/common/driver_finder.py", line 47, in get_browser_path
    return self._binary_paths()["browser_path"]
  File "/usr/local/lib/python3.10/site-packages/selenium/webdriver/common/driver_finder.py", line 78, in _binary_paths
    raise NoSuchDriverException(msg) from err
selenium.common.exceptions.NoSuchDriverException: Message: Unable to obtain driver for chrome; For documentation on this error, please visit: https://www.selenium.dev/documentation/webdriver/troubleshooting/errors/driver_location

2025-01-31 02:22:57,863 - INFO - Processing record 0 (URL: https://www.morphosource.org/concern/media/000705609?locale=en)
2025-01-31 02:22:57,863 - INFO - Setting up new Chrome driver
2025-01-31 02:22:58,009 - ERROR - Error on attempt 1 for https://www.morphosource.org/concern/media/000705609?locale=en: Message: Unable to obtain driver for chrome; For documentation on this error, please visit: https://www.selenium.dev/documentation/webdriver/troubleshooting/errors/driver_location
Traceback (most recent call last):
  File "/usr/local/lib/python3.10/site-packages/selenium/webdriver/common/driver_finder.py", line 67, in _binary_paths
    output = SeleniumManager().binary_paths(self._to_args())
  File "/usr/local/lib/python3.10/site-packages/selenium/webdriver/common/selenium_manager.py", line 55, in binary_paths
    return self._run(args)
  File "/usr/local/lib/python3.10/site-packages/selenium/webdriver/common/selenium_manager.py", line 129, in _run
    raise WebDriverException(
selenium.common.exceptions.WebDriverException: Message: Unsuccessful command executed: /usr/local/lib/python3.10/site-packages/selenium/webdriver/common/linux/selenium-manager --browser chrome --browser-path /usr/bin/google-chrome --language-binding python --output json; code: 65
{'code': 65, 'message': 'Browser path does not exist: /usr/bin/google-chrome', 'driver_path': '', 'browser_path': ''}



The above exception was the direct cause of the following exception:

Traceback (most recent call last):
  File "/Users/jt/Documents/GitHub/Parquet-Processor/.github/scripts/test_parquet_processor.py", line 298, in process_url_batch
    driver = setup_driver()
  File "/Users/jt/Documents/GitHub/Parquet-Processor/.github/scripts/test_parquet_processor.py", line 72, in setup_driver
    driver = webdriver.Chrome(options=chrome_options)
  File "/usr/local/lib/python3.10/site-packages/selenium/webdriver/chrome/webdriver.py", line 45, in __init__
    super().__init__(
  File "/usr/local/lib/python3.10/site-packages/selenium/webdriver/chromium/webdriver.py", line 50, in __init__
    if finder.get_browser_path():
  File "/usr/local/lib/python3.10/site-packages/selenium/webdriver/common/driver_finder.py", line 47, in get_browser_path
    return self._binary_paths()["browser_path"]
  File "/usr/local/lib/python3.10/site-packages/selenium/webdriver/common/driver_finder.py", line 78, in _binary_paths
    raise NoSuchDriverException(msg) from err
selenium.common.exceptions.NoSuchDriverException: Message: Unable to obtain driver for chrome; For documentation on this error, please visit: https://www.selenium.dev/documentation/webdriver/troubleshooting/errors/driver_location

2025-01-31 02:22:58,011 - INFO - Retrying https://www.morphosource.org/concern/media/000705609?locale=en after error...
2025-01-31 02:22:59,019 - INFO - Setting up new Chrome driver
2025-01-31 02:22:59,163 - ERROR - Error on attempt 2 for https://www.morphosource.org/concern/media/000705609?locale=en: Message: Unable to obtain driver for chrome; For documentation on this error, please visit: https://www.selenium.dev/documentation/webdriver/troubleshooting/errors/driver_location
Traceback (most recent call last):
  File "/usr/local/lib/python3.10/site-packages/selenium/webdriver/common/driver_finder.py", line 67, in _binary_paths
    output = SeleniumManager().binary_paths(self._to_args())
  File "/usr/local/lib/python3.10/site-packages/selenium/webdriver/common/selenium_manager.py", line 55, in binary_paths
    return self._run(args)
  File "/usr/local/lib/python3.10/site-packages/selenium/webdriver/common/selenium_manager.py", line 129, in _run
    raise WebDriverException(
selenium.common.exceptions.WebDriverException: Message: Unsuccessful command executed: /usr/local/lib/python3.10/site-packages/selenium/webdriver/common/linux/selenium-manager --browser chrome --browser-path /usr/bin/google-chrome --language-binding python --output json; code: 65
{'code': 65, 'message': 'Browser path does not exist: /usr/bin/google-chrome', 'driver_path': '', 'browser_path': ''}



The above exception was the direct cause of the following exception:

Traceback (most recent call last):
  File "/Users/jt/Documents/GitHub/Parquet-Processor/.github/scripts/test_parquet_processor.py", line 298, in process_url_batch
    driver = setup_driver()
  File "/Users/jt/Documents/GitHub/Parquet-Processor/.github/scripts/test_parquet_processor.py", line 72, in setup_driver
    driver = webdriver.Chrome(options=chrome_options)
  File "/usr/local/lib/python3.10/site-packages/selenium/webdriver/chrome/webdriver.py", line 45, in __init__
    super().__init__(
  File "/usr/local/lib/python3.10/site-packages/selenium/webdriver/chromium/webdriver.py", line 50, in __init__
    if finder.get_browser_path():
  File "/usr/local/lib/python3.10/site-packages/selenium/webdriver/common/driver_finder.py", line 47, in get_browser_path
    return self._binary_paths()["browser_path"]
  File "/usr/local/lib/python3.10/site-packages/selenium/webdriver/common/driver_finder.py", line 78, in _binary_paths
    raise NoSuchDriverException(msg) from err
selenium.common.exceptions.NoSuchDriverException: Message: Unable to obtain driver for chrome; For documentation on this error, please visit: https://www.selenium.dev/documentation/webdriver/troubleshooting/errors/driver_location

2025-01-31 02:22:59,165 - INFO - Processing record 0 (URL: https://www.morphosource.org/concern/media/000705605?locale=en)
2025-01-31 02:22:59,165 - INFO - Setting up new Chrome driver
2025-01-31 02:22:59,304 - ERROR - Error on attempt 1 for https://www.morphosource.org/concern/media/000705605?locale=en: Message: Unable to obtain driver for chrome; For documentation on this error, please visit: https://www.selenium.dev/documentation/webdriver/troubleshooting/errors/driver_location
Traceback (most recent call last):
  File "/usr/local/lib/python3.10/site-packages/selenium/webdriver/common/driver_finder.py", line 67, in _binary_paths
    output = SeleniumManager().binary_paths(self._to_args())
  File "/usr/local/lib/python3.10/site-packages/selenium/webdriver/common/selenium_manager.py", line 55, in binary_paths
    return self._run(args)
  File "/usr/local/lib/python3.10/site-packages/selenium/webdriver/common/selenium_manager.py", line 129, in _run
    raise WebDriverException(
selenium.common.exceptions.WebDriverException: Message: Unsuccessful command executed: /usr/local/lib/python3.10/site-packages/selenium/webdriver/common/linux/selenium-manager --browser chrome --browser-path /usr/bin/google-chrome --language-binding python --output json; code: 65
{'code': 65, 'message': 'Browser path does not exist: /usr/bin/google-chrome', 'driver_path': '', 'browser_path': ''}



The above exception was the direct cause of the following exception:

Traceback (most recent call last):
  File "/Users/jt/Documents/GitHub/Parquet-Processor/.github/scripts/test_parquet_processor.py", line 298, in process_url_batch
    driver = setup_driver()
  File "/Users/jt/Documents/GitHub/Parquet-Processor/.github/scripts/test_parquet_processor.py", line 72, in setup_driver
    driver = webdriver.Chrome(options=chrome_options)
  File "/usr/local/lib/python3.10/site-packages/selenium/webdriver/chrome/webdriver.py", line 45, in __init__
    super().__init__(
  File "/usr/local/lib/python3.10/site-packages/selenium/webdriver/chromium/webdriver.py", line 50, in __init__
    if finder.get_browser_path():
  File "/usr/local/lib/python3.10/site-packages/selenium/webdriver/common/driver_finder.py", line 47, in get_browser_path
    return self._binary_paths()["browser_path"]
  File "/usr/local/lib/python3.10/site-packages/selenium/webdriver/common/driver_finder.py", line 78, in _binary_paths
    raise NoSuchDriverException(msg) from err
selenium.common.exceptions.NoSuchDriverException: Message: Unable to obtain driver for chrome; For documentation on this error, please visit: https://www.selenium.dev/documentation/webdriver/troubleshooting/errors/driver_location

2025-01-31 02:22:59,305 - INFO - Retrying https://www.morphosource.org/concern/media/000705605?locale=en after error...
2025-01-31 02:23:00,310 - INFO - Setting up new Chrome driver
2025-01-31 02:23:00,488 - ERROR - Error on attempt 2 for https://www.morphosource.org/concern/media/000705605?locale=en: Message: Unable to obtain driver for chrome; For documentation on this error, please visit: https://www.selenium.dev/documentation/webdriver/troubleshooting/errors/driver_location
Traceback (most recent call last):
  File "/usr/local/lib/python3.10/site-packages/selenium/webdriver/common/driver_finder.py", line 67, in _binary_paths
    output = SeleniumManager().binary_paths(self._to_args())
  File "/usr/local/lib/python3.10/site-packages/selenium/webdriver/common/selenium_manager.py", line 55, in binary_paths
    return self._run(args)
  File "/usr/local/lib/python3.10/site-packages/selenium/webdriver/common/selenium_manager.py", line 129, in _run
    raise WebDriverException(
selenium.common.exceptions.WebDriverException: Message: Unsuccessful command executed: /usr/local/lib/python3.10/site-packages/selenium/webdriver/common/linux/selenium-manager --browser chrome --browser-path /usr/bin/google-chrome --language-binding python --output json; code: 65
{'code': 65, 'message': 'Browser path does not exist: /usr/bin/google-chrome', 'driver_path': '', 'browser_path': ''}



The above exception was the direct cause of the following exception:

Traceback (most recent call last):
  File "/Users/jt/Documents/GitHub/Parquet-Processor/.github/scripts/test_parquet_processor.py", line 298, in process_url_batch
    driver = setup_driver()
  File "/Users/jt/Documents/GitHub/Parquet-Processor/.github/scripts/test_parquet_processor.py", line 72, in setup_driver
    driver = webdriver.Chrome(options=chrome_options)
  File "/usr/local/lib/python3.10/site-packages/selenium/webdriver/chrome/webdriver.py", line 45, in __init__
    super().__init__(
  File "/usr/local/lib/python3.10/site-packages/selenium/webdriver/chromium/webdriver.py", line 50, in __init__
    if finder.get_browser_path():
  File "/usr/local/lib/python3.10/site-packages/selenium/webdriver/common/driver_finder.py", line 47, in get_browser_path
    return self._binary_paths()["browser_path"]
  File "/usr/local/lib/python3.10/site-packages/selenium/webdriver/common/driver_finder.py", line 78, in _binary_paths
    raise NoSuchDriverException(msg) from err
selenium.common.exceptions.NoSuchDriverException: Message: Unable to obtain driver for chrome; For documentation on this error, please visit: https://www.selenium.dev/documentation/webdriver/troubleshooting/errors/driver_location

2025-01-31 02:23:00,490 - INFO - Processing record 0 (URL: https://www.morphosource.org/concern/media/000705594?locale=en)
2025-01-31 02:23:00,491 - INFO - Setting up new Chrome driver
2025-01-31 02:23:00,632 - ERROR - Error on attempt 1 for https://www.morphosource.org/concern/media/000705594?locale=en: Message: Unable to obtain driver for chrome; For documentation on this error, please visit: https://www.selenium.dev/documentation/webdriver/troubleshooting/errors/driver_location
Traceback (most recent call last):
  File "/usr/local/lib/python3.10/site-packages/selenium/webdriver/common/driver_finder.py", line 67, in _binary_paths
    output = SeleniumManager().binary_paths(self._to_args())
  File "/usr/local/lib/python3.10/site-packages/selenium/webdriver/common/selenium_manager.py", line 55, in binary_paths
    return self._run(args)
  File "/usr/local/lib/python3.10/site-packages/selenium/webdriver/common/selenium_manager.py", line 129, in _run
    raise WebDriverException(
selenium.common.exceptions.WebDriverException: Message: Unsuccessful command executed: /usr/local/lib/python3.10/site-packages/selenium/webdriver/common/linux/selenium-manager --browser chrome --browser-path /usr/bin/google-chrome --language-binding python --output json; code: 65
{'code': 65, 'message': 'Browser path does not exist: /usr/bin/google-chrome', 'driver_path': '', 'browser_path': ''}



The above exception was the direct cause of the following exception:

Traceback (most recent call last):
  File "/Users/jt/Documents/GitHub/Parquet-Processor/.github/scripts/test_parquet_processor.py", line 298, in process_url_batch
    driver = setup_driver()
  File "/Users/jt/Documents/GitHub/Parquet-Processor/.github/scripts/test_parquet_processor.py", line 72, in setup_driver
    driver = webdriver.Chrome(options=chrome_options)
  File "/usr/local/lib/python3.10/site-packages/selenium/webdriver/chrome/webdriver.py", line 45, in __init__
    super().__init__(
  File "/usr/local/lib/python3.10/site-packages/selenium/webdriver/chromium/webdriver.py", line 50, in __init__
    if finder.get_browser_path():
  File "/usr/local/lib/python3.10/site-packages/selenium/webdriver/common/driver_finder.py", line 47, in get_browser_path
    return self._binary_paths()["browser_path"]
  File "/usr/local/lib/python3.10/site-packages/selenium/webdriver/common/driver_finder.py", line 78, in _binary_paths
    raise NoSuchDriverException(msg) from err
selenium.common.exceptions.NoSuchDriverException: Message: Unable to obtain driver for chrome; For documentation on this error, please visit: https://www.selenium.dev/documentation/webdriver/troubleshooting/errors/driver_location

2025-01-31 02:23:00,634 - INFO - Retrying https://www.morphosource.org/concern/media/000705594?locale=en after error...
2025-01-31 02:23:01,644 - INFO - Setting up new Chrome driver
2025-01-31 02:23:01,919 - ERROR - Error on attempt 2 for https://www.morphosource.org/concern/media/000705594?locale=en: Message: Unable to obtain driver for chrome; For documentation on this error, please visit: https://www.selenium.dev/documentation/webdriver/troubleshooting/errors/driver_location
Traceback (most recent call last):
  File "/usr/local/lib/python3.10/site-packages/selenium/webdriver/common/driver_finder.py", line 67, in _binary_paths
    output = SeleniumManager().binary_paths(self._to_args())
  File "/usr/local/lib/python3.10/site-packages/selenium/webdriver/common/selenium_manager.py", line 55, in binary_paths
    return self._run(args)
  File "/usr/local/lib/python3.10/site-packages/selenium/webdriver/common/selenium_manager.py", line 129, in _run
    raise WebDriverException(
selenium.common.exceptions.WebDriverException: Message: Unsuccessful command executed: /usr/local/lib/python3.10/site-packages/selenium/webdriver/common/linux/selenium-manager --browser chrome --browser-path /usr/bin/google-chrome --language-binding python --output json; code: 65
{'code': 65, 'message': 'Browser path does not exist: /usr/bin/google-chrome', 'driver_path': '', 'browser_path': ''}



The above exception was the direct cause of the following exception:

Traceback (most recent call last):
  File "/Users/jt/Documents/GitHub/Parquet-Processor/.github/scripts/test_parquet_processor.py", line 298, in process_url_batch
    driver = setup_driver()
  File "/Users/jt/Documents/GitHub/Parquet-Processor/.github/scripts/test_parquet_processor.py", line 72, in setup_driver
    driver = webdriver.Chrome(options=chrome_options)
  File "/usr/local/lib/python3.10/site-packages/selenium/webdriver/chrome/webdriver.py", line 45, in __init__
    super().__init__(
  File "/usr/local/lib/python3.10/site-packages/selenium/webdriver/chromium/webdriver.py", line 50, in __init__
    if finder.get_browser_path():
  File "/usr/local/lib/python3.10/site-packages/selenium/webdriver/common/driver_finder.py", line 47, in get_browser_path
    return self._binary_paths()["browser_path"]
  File "/usr/local/lib/python3.10/site-packages/selenium/webdriver/common/driver_finder.py", line 78, in _binary_paths
    raise NoSuchDriverException(msg) from err
selenium.common.exceptions.NoSuchDriverException: Message: Unable to obtain driver for chrome; For documentation on this error, please visit: https://www.selenium.dev/documentation/webdriver/troubleshooting/errors/driver_location

2025-01-31 02:23:01,922 - INFO - Processing record 0 (URL: https://www.morphosource.org/concern/media/000705592?locale=en)
2025-01-31 02:23:01,923 - INFO - Setting up new Chrome driver
2025-01-31 02:23:02,143 - ERROR - Error on attempt 1 for https://www.morphosource.org/concern/media/000705592?locale=en: Message: Unable to obtain driver for chrome; For documentation on this error, please visit: https://www.selenium.dev/documentation/webdriver/troubleshooting/errors/driver_location
Traceback (most recent call last):
  File "/usr/local/lib/python3.10/site-packages/selenium/webdriver/common/driver_finder.py", line 67, in _binary_paths
    output = SeleniumManager().binary_paths(self._to_args())
  File "/usr/local/lib/python3.10/site-packages/selenium/webdriver/common/selenium_manager.py", line 55, in binary_paths
    return self._run(args)
  File "/usr/local/lib/python3.10/site-packages/selenium/webdriver/common/selenium_manager.py", line 129, in _run
    raise WebDriverException(
selenium.common.exceptions.WebDriverException: Message: Unsuccessful command executed: /usr/local/lib/python3.10/site-packages/selenium/webdriver/common/linux/selenium-manager --browser chrome --browser-path /usr/bin/google-chrome --language-binding python --output json; code: 65
{'code': 65, 'message': 'Browser path does not exist: /usr/bin/google-chrome', 'driver_path': '', 'browser_path': ''}



The above exception was the direct cause of the following exception:

Traceback (most recent call last):
  File "/Users/jt/Documents/GitHub/Parquet-Processor/.github/scripts/test_parquet_processor.py", line 298, in process_url_batch
    driver = setup_driver()
  File "/Users/jt/Documents/GitHub/Parquet-Processor/.github/scripts/test_parquet_processor.py", line 72, in setup_driver
    driver = webdriver.Chrome(options=chrome_options)
  File "/usr/local/lib/python3.10/site-packages/selenium/webdriver/chrome/webdriver.py", line 45, in __init__
    super().__init__(
  File "/usr/local/lib/python3.10/site-packages/selenium/webdriver/chromium/webdriver.py", line 50, in __init__
    if finder.get_browser_path():
  File "/usr/local/lib/python3.10/site-packages/selenium/webdriver/common/driver_finder.py", line 47, in get_browser_path
    return self._binary_paths()["browser_path"]
  File "/usr/local/lib/python3.10/site-packages/selenium/webdriver/common/driver_finder.py", line 78, in _binary_paths
    raise NoSuchDriverException(msg) from err
selenium.common.exceptions.NoSuchDriverException: Message: Unable to obtain driver for chrome; For documentation on this error, please visit: https://www.selenium.dev/documentation/webdriver/troubleshooting/errors/driver_location

2025-01-31 02:23:02,145 - INFO - Retrying https://www.morphosource.org/concern/media/000705592?locale=en after error...
2025-01-31 02:23:03,174 - INFO - Setting up new Chrome driver
2025-01-31 02:23:03,363 - ERROR - Error on attempt 2 for https://www.morphosource.org/concern/media/000705592?locale=en: Message: Unable to obtain driver for chrome; For documentation on this error, please visit: https://www.selenium.dev/documentation/webdriver/troubleshooting/errors/driver_location
Traceback (most recent call last):
  File "/usr/local/lib/python3.10/site-packages/selenium/webdriver/common/driver_finder.py", line 67, in _binary_paths
    output = SeleniumManager().binary_paths(self._to_args())
  File "/usr/local/lib/python3.10/site-packages/selenium/webdriver/common/selenium_manager.py", line 55, in binary_paths
    return self._run(args)
  File "/usr/local/lib/python3.10/site-packages/selenium/webdriver/common/selenium_manager.py", line 129, in _run
    raise WebDriverException(
selenium.common.exceptions.WebDriverException: Message: Unsuccessful command executed: /usr/local/lib/python3.10/site-packages/selenium/webdriver/common/linux/selenium-manager --browser chrome --browser-path /usr/bin/google-chrome --language-binding python --output json; code: 65
{'code': 65, 'message': 'Browser path does not exist: /usr/bin/google-chrome', 'driver_path': '', 'browser_path': ''}



The above exception was the direct cause of the following exception:

Traceback (most recent call last):
  File "/Users/jt/Documents/GitHub/Parquet-Processor/.github/scripts/test_parquet_processor.py", line 298, in process_url_batch
    driver = setup_driver()
  File "/Users/jt/Documents/GitHub/Parquet-Processor/.github/scripts/test_parquet_processor.py", line 72, in setup_driver
    driver = webdriver.Chrome(options=chrome_options)
  File "/usr/local/lib/python3.10/site-packages/selenium/webdriver/chrome/webdriver.py", line 45, in __init__
    super().__init__(
  File "/usr/local/lib/python3.10/site-packages/selenium/webdriver/chromium/webdriver.py", line 50, in __init__
    if finder.get_browser_path():
  File "/usr/local/lib/python3.10/site-packages/selenium/webdriver/common/driver_finder.py", line 47, in get_browser_path
    return self._binary_paths()["browser_path"]
  File "/usr/local/lib/python3.10/site-packages/selenium/webdriver/common/driver_finder.py", line 78, in _binary_paths
    raise NoSuchDriverException(msg) from err
selenium.common.exceptions.NoSuchDriverException: Message: Unable to obtain driver for chrome; For documentation on this error, please visit: https://www.selenium.dev/documentation/webdriver/troubleshooting/errors/driver_location

2025-01-31 02:23:03,366 - INFO - Processing record 0 (URL: https://www.morphosource.org/concern/media/000705580?locale=en)
2025-01-31 02:23:03,366 - INFO - Setting up new Chrome driver
2025-01-31 02:23:03,558 - ERROR - Error on attempt 1 for https://www.morphosource.org/concern/media/000705580?locale=en: Message: Unable to obtain driver for chrome; For documentation on this error, please visit: https://www.selenium.dev/documentation/webdriver/troubleshooting/errors/driver_location
Traceback (most recent call last):
  File "/usr/local/lib/python3.10/site-packages/selenium/webdriver/common/driver_finder.py", line 67, in _binary_paths
    output = SeleniumManager().binary_paths(self._to_args())
  File "/usr/local/lib/python3.10/site-packages/selenium/webdriver/common/selenium_manager.py", line 55, in binary_paths
    return self._run(args)
  File "/usr/local/lib/python3.10/site-packages/selenium/webdriver/common/selenium_manager.py", line 129, in _run
    raise WebDriverException(
selenium.common.exceptions.WebDriverException: Message: Unsuccessful command executed: /usr/local/lib/python3.10/site-packages/selenium/webdriver/common/linux/selenium-manager --browser chrome --browser-path /usr/bin/google-chrome --language-binding python --output json; code: 65
{'code': 65, 'message': 'Browser path does not exist: /usr/bin/google-chrome', 'driver_path': '', 'browser_path': ''}



The above exception was the direct cause of the following exception:

Traceback (most recent call last):
  File "/Users/jt/Documents/GitHub/Parquet-Processor/.github/scripts/test_parquet_processor.py", line 298, in process_url_batch
    driver = setup_driver()
  File "/Users/jt/Documents/GitHub/Parquet-Processor/.github/scripts/test_parquet_processor.py", line 72, in setup_driver
    driver = webdriver.Chrome(options=chrome_options)
  File "/usr/local/lib/python3.10/site-packages/selenium/webdriver/chrome/webdriver.py", line 45, in __init__
    super().__init__(
  File "/usr/local/lib/python3.10/site-packages/selenium/webdriver/chromium/webdriver.py", line 50, in __init__
    if finder.get_browser_path():
  File "/usr/local/lib/python3.10/site-packages/selenium/webdriver/common/driver_finder.py", line 47, in get_browser_path
    return self._binary_paths()["browser_path"]
  File "/usr/local/lib/python3.10/site-packages/selenium/webdriver/common/driver_finder.py", line 78, in _binary_paths
    raise NoSuchDriverException(msg) from err
selenium.common.exceptions.NoSuchDriverException: Message: Unable to obtain driver for chrome; For documentation on this error, please visit: https://www.selenium.dev/documentation/webdriver/troubleshooting/errors/driver_location

2025-01-31 02:23:03,561 - INFO - Retrying https://www.morphosource.org/concern/media/000705580?locale=en after error...
2025-01-31 02:23:04,570 - INFO - Setting up new Chrome driver
2025-01-31 02:23:04,746 - ERROR - Error on attempt 2 for https://www.morphosource.org/concern/media/000705580?locale=en: Message: Unable to obtain driver for chrome; For documentation on this error, please visit: https://www.selenium.dev/documentation/webdriver/troubleshooting/errors/driver_location
Traceback (most recent call last):
  File "/usr/local/lib/python3.10/site-packages/selenium/webdriver/common/driver_finder.py", line 67, in _binary_paths
    output = SeleniumManager().binary_paths(self._to_args())
  File "/usr/local/lib/python3.10/site-packages/selenium/webdriver/common/selenium_manager.py", line 55, in binary_paths
    return self._run(args)
  File "/usr/local/lib/python3.10/site-packages/selenium/webdriver/common/selenium_manager.py", line 129, in _run
    raise WebDriverException(
selenium.common.exceptions.WebDriverException: Message: Unsuccessful command executed: /usr/local/lib/python3.10/site-packages/selenium/webdriver/common/linux/selenium-manager --browser chrome --browser-path /usr/bin/google-chrome --language-binding python --output json; code: 65
{'code': 65, 'message': 'Browser path does not exist: /usr/bin/google-chrome', 'driver_path': '', 'browser_path': ''}



The above exception was the direct cause of the following exception:

Traceback (most recent call last):
  File "/Users/jt/Documents/GitHub/Parquet-Processor/.github/scripts/test_parquet_processor.py", line 298, in process_url_batch
    driver = setup_driver()
  File "/Users/jt/Documents/GitHub/Parquet-Processor/.github/scripts/test_parquet_processor.py", line 72, in setup_driver
    driver = webdriver.Chrome(options=chrome_options)
  File "/usr/local/lib/python3.10/site-packages/selenium/webdriver/chrome/webdriver.py", line 45, in __init__
    super().__init__(
  File "/usr/local/lib/python3.10/site-packages/selenium/webdriver/chromium/webdriver.py", line 50, in __init__
    if finder.get_browser_path():
  File "/usr/local/lib/python3.10/site-packages/selenium/webdriver/common/driver_finder.py", line 47, in get_browser_path
    return self._binary_paths()["browser_path"]
  File "/usr/local/lib/python3.10/site-packages/selenium/webdriver/common/driver_finder.py", line 78, in _binary_paths
    raise NoSuchDriverException(msg) from err
selenium.common.exceptions.NoSuchDriverException: Message: Unable to obtain driver for chrome; For documentation on this error, please visit: https://www.selenium.dev/documentation/webdriver/troubleshooting/errors/driver_location

2025-01-31 02:23:04,749 - INFO - Processing record 0 (URL: https://www.morphosource.org/concern/media/000705568?locale=en)
2025-01-31 02:23:04,750 - INFO - Setting up new Chrome driver
2025-01-31 02:23:04,909 - ERROR - Error on attempt 1 for https://www.morphosource.org/concern/media/000705568?locale=en: Message: Unable to obtain driver for chrome; For documentation on this error, please visit: https://www.selenium.dev/documentation/webdriver/troubleshooting/errors/driver_location
Traceback (most recent call last):
  File "/usr/local/lib/python3.10/site-packages/selenium/webdriver/common/driver_finder.py", line 67, in _binary_paths
    output = SeleniumManager().binary_paths(self._to_args())
  File "/usr/local/lib/python3.10/site-packages/selenium/webdriver/common/selenium_manager.py", line 55, in binary_paths
    return self._run(args)
  File "/usr/local/lib/python3.10/site-packages/selenium/webdriver/common/selenium_manager.py", line 129, in _run
    raise WebDriverException(
selenium.common.exceptions.WebDriverException: Message: Unsuccessful command executed: /usr/local/lib/python3.10/site-packages/selenium/webdriver/common/linux/selenium-manager --browser chrome --browser-path /usr/bin/google-chrome --language-binding python --output json; code: 65
{'code': 65, 'message': 'Browser path does not exist: /usr/bin/google-chrome', 'driver_path': '', 'browser_path': ''}



The above exception was the direct cause of the following exception:

Traceback (most recent call last):
  File "/Users/jt/Documents/GitHub/Parquet-Processor/.github/scripts/test_parquet_processor.py", line 298, in process_url_batch
    driver = setup_driver()
  File "/Users/jt/Documents/GitHub/Parquet-Processor/.github/scripts/test_parquet_processor.py", line 72, in setup_driver
    driver = webdriver.Chrome(options=chrome_options)
  File "/usr/local/lib/python3.10/site-packages/selenium/webdriver/chrome/webdriver.py", line 45, in __init__
    super().__init__(
  File "/usr/local/lib/python3.10/site-packages/selenium/webdriver/chromium/webdriver.py", line 50, in __init__
    if finder.get_browser_path():
  File "/usr/local/lib/python3.10/site-packages/selenium/webdriver/common/driver_finder.py", line 47, in get_browser_path
    return self._binary_paths()["browser_path"]
  File "/usr/local/lib/python3.10/site-packages/selenium/webdriver/common/driver_finder.py", line 78, in _binary_paths
    raise NoSuchDriverException(msg) from err
selenium.common.exceptions.NoSuchDriverException: Message: Unable to obtain driver for chrome; For documentation on this error, please visit: https://www.selenium.dev/documentation/webdriver/troubleshooting/errors/driver_location

2025-01-31 02:23:04,911 - INFO - Retrying https://www.morphosource.org/concern/media/000705568?locale=en after error...
2025-01-31 02:23:05,915 - INFO - Setting up new Chrome driver
2025-01-31 02:23:06,067 - ERROR - Error on attempt 2 for https://www.morphosource.org/concern/media/000705568?locale=en: Message: Unable to obtain driver for chrome; For documentation on this error, please visit: https://www.selenium.dev/documentation/webdriver/troubleshooting/errors/driver_location
Traceback (most recent call last):
  File "/usr/local/lib/python3.10/site-packages/selenium/webdriver/common/driver_finder.py", line 67, in _binary_paths
    output = SeleniumManager().binary_paths(self._to_args())
  File "/usr/local/lib/python3.10/site-packages/selenium/webdriver/common/selenium_manager.py", line 55, in binary_paths
    return self._run(args)
  File "/usr/local/lib/python3.10/site-packages/selenium/webdriver/common/selenium_manager.py", line 129, in _run
    raise WebDriverException(
selenium.common.exceptions.WebDriverException: Message: Unsuccessful command executed: /usr/local/lib/python3.10/site-packages/selenium/webdriver/common/linux/selenium-manager --browser chrome --browser-path /usr/bin/google-chrome --language-binding python --output json; code: 65
{'code': 65, 'message': 'Browser path does not exist: /usr/bin/google-chrome', 'driver_path': '', 'browser_path': ''}



The above exception was the direct cause of the following exception:

Traceback (most recent call last):
  File "/Users/jt/Documents/GitHub/Parquet-Processor/.github/scripts/test_parquet_processor.py", line 298, in process_url_batch
    driver = setup_driver()
  File "/Users/jt/Documents/GitHub/Parquet-Processor/.github/scripts/test_parquet_processor.py", line 72, in setup_driver
    driver = webdriver.Chrome(options=chrome_options)
  File "/usr/local/lib/python3.10/site-packages/selenium/webdriver/chrome/webdriver.py", line 45, in __init__
    super().__init__(
  File "/usr/local/lib/python3.10/site-packages/selenium/webdriver/chromium/webdriver.py", line 50, in __init__
    if finder.get_browser_path():
  File "/usr/local/lib/python3.10/site-packages/selenium/webdriver/common/driver_finder.py", line 47, in get_browser_path
    return self._binary_paths()["browser_path"]
  File "/usr/local/lib/python3.10/site-packages/selenium/webdriver/common/driver_finder.py", line 78, in _binary_paths
    raise NoSuchDriverException(msg) from err
selenium.common.exceptions.NoSuchDriverException: Message: Unable to obtain driver for chrome; For documentation on this error, please visit: https://www.selenium.dev/documentation/webdriver/troubleshooting/errors/driver_location

2025-01-31 02:23:06,070 - INFO - Processing record 0 (URL: https://www.morphosource.org/concern/media/000705560?locale=en)
2025-01-31 02:23:06,071 - INFO - Setting up new Chrome driver
2025-01-31 02:23:06,212 - ERROR - Error on attempt 1 for https://www.morphosource.org/concern/media/000705560?locale=en: Message: Unable to obtain driver for chrome; For documentation on this error, please visit: https://www.selenium.dev/documentation/webdriver/troubleshooting/errors/driver_location
Traceback (most recent call last):
  File "/usr/local/lib/python3.10/site-packages/selenium/webdriver/common/driver_finder.py", line 67, in _binary_paths
    output = SeleniumManager().binary_paths(self._to_args())
  File "/usr/local/lib/python3.10/site-packages/selenium/webdriver/common/selenium_manager.py", line 55, in binary_paths
    return self._run(args)
  File "/usr/local/lib/python3.10/site-packages/selenium/webdriver/common/selenium_manager.py", line 129, in _run
    raise WebDriverException(
selenium.common.exceptions.WebDriverException: Message: Unsuccessful command executed: /usr/local/lib/python3.10/site-packages/selenium/webdriver/common/linux/selenium-manager --browser chrome --browser-path /usr/bin/google-chrome --language-binding python --output json; code: 65
{'code': 65, 'message': 'Browser path does not exist: /usr/bin/google-chrome', 'driver_path': '', 'browser_path': ''}



The above exception was the direct cause of the following exception:

Traceback (most recent call last):
  File "/Users/jt/Documents/GitHub/Parquet-Processor/.github/scripts/test_parquet_processor.py", line 298, in process_url_batch
    driver = setup_driver()
  File "/Users/jt/Documents/GitHub/Parquet-Processor/.github/scripts/test_parquet_processor.py", line 72, in setup_driver
    driver = webdriver.Chrome(options=chrome_options)
  File "/usr/local/lib/python3.10/site-packages/selenium/webdriver/chrome/webdriver.py", line 45, in __init__
    super().__init__(
  File "/usr/local/lib/python3.10/site-packages/selenium/webdriver/chromium/webdriver.py", line 50, in __init__
    if finder.get_browser_path():
  File "/usr/local/lib/python3.10/site-packages/selenium/webdriver/common/driver_finder.py", line 47, in get_browser_path
    return self._binary_paths()["browser_path"]
  File "/usr/local/lib/python3.10/site-packages/selenium/webdriver/common/driver_finder.py", line 78, in _binary_paths
    raise NoSuchDriverException(msg) from err
selenium.common.exceptions.NoSuchDriverException: Message: Unable to obtain driver for chrome; For documentation on this error, please visit: https://www.selenium.dev/documentation/webdriver/troubleshooting/errors/driver_location

2025-01-31 02:23:06,213 - INFO - Retrying https://www.morphosource.org/concern/media/000705560?locale=en after error...
2025-01-31 02:23:07,221 - INFO - Setting up new Chrome driver
2025-01-31 02:23:07,363 - ERROR - Error on attempt 2 for https://www.morphosource.org/concern/media/000705560?locale=en: Message: Unable to obtain driver for chrome; For documentation on this error, please visit: https://www.selenium.dev/documentation/webdriver/troubleshooting/errors/driver_location
Traceback (most recent call last):
  File "/usr/local/lib/python3.10/site-packages/selenium/webdriver/common/driver_finder.py", line 67, in _binary_paths
    output = SeleniumManager().binary_paths(self._to_args())
  File "/usr/local/lib/python3.10/site-packages/selenium/webdriver/common/selenium_manager.py", line 55, in binary_paths
    return self._run(args)
  File "/usr/local/lib/python3.10/site-packages/selenium/webdriver/common/selenium_manager.py", line 129, in _run
    raise WebDriverException(
selenium.common.exceptions.WebDriverException: Message: Unsuccessful command executed: /usr/local/lib/python3.10/site-packages/selenium/webdriver/common/linux/selenium-manager --browser chrome --browser-path /usr/bin/google-chrome --language-binding python --output json; code: 65
{'code': 65, 'message': 'Browser path does not exist: /usr/bin/google-chrome', 'driver_path': '', 'browser_path': ''}



The above exception was the direct cause of the following exception:

Traceback (most recent call last):
  File "/Users/jt/Documents/GitHub/Parquet-Processor/.github/scripts/test_parquet_processor.py", line 298, in process_url_batch
    driver = setup_driver()
  File "/Users/jt/Documents/GitHub/Parquet-Processor/.github/scripts/test_parquet_processor.py", line 72, in setup_driver
    driver = webdriver.Chrome(options=chrome_options)
  File "/usr/local/lib/python3.10/site-packages/selenium/webdriver/chrome/webdriver.py", line 45, in __init__
    super().__init__(
  File "/usr/local/lib/python3.10/site-packages/selenium/webdriver/chromium/webdriver.py", line 50, in __init__
    if finder.get_browser_path():
  File "/usr/local/lib/python3.10/site-packages/selenium/webdriver/common/driver_finder.py", line 47, in get_browser_path
    return self._binary_paths()["browser_path"]
  File "/usr/local/lib/python3.10/site-packages/selenium/webdriver/common/driver_finder.py", line 78, in _binary_paths
    raise NoSuchDriverException(msg) from err
selenium.common.exceptions.NoSuchDriverException: Message: Unable to obtain driver for chrome; For documentation on this error, please visit: https://www.selenium.dev/documentation/webdriver/troubleshooting/errors/driver_location

2025-01-31 02:23:07,366 - INFO - Processing record 0 (URL: https://www.morphosource.org/concern/media/000705559?locale=en)
2025-01-31 02:23:07,366 - INFO - Setting up new Chrome driver
2025-01-31 02:23:07,502 - ERROR - Error on attempt 1 for https://www.morphosource.org/concern/media/000705559?locale=en: Message: Unable to obtain driver for chrome; For documentation on this error, please visit: https://www.selenium.dev/documentation/webdriver/troubleshooting/errors/driver_location
Traceback (most recent call last):
  File "/usr/local/lib/python3.10/site-packages/selenium/webdriver/common/driver_finder.py", line 67, in _binary_paths
    output = SeleniumManager().binary_paths(self._to_args())
  File "/usr/local/lib/python3.10/site-packages/selenium/webdriver/common/selenium_manager.py", line 55, in binary_paths
    return self._run(args)
  File "/usr/local/lib/python3.10/site-packages/selenium/webdriver/common/selenium_manager.py", line 129, in _run
    raise WebDriverException(
selenium.common.exceptions.WebDriverException: Message: Unsuccessful command executed: /usr/local/lib/python3.10/site-packages/selenium/webdriver/common/linux/selenium-manager --browser chrome --browser-path /usr/bin/google-chrome --language-binding python --output json; code: 65
{'code': 65, 'message': 'Browser path does not exist: /usr/bin/google-chrome', 'driver_path': '', 'browser_path': ''}



The above exception was the direct cause of the following exception:

Traceback (most recent call last):
  File "/Users/jt/Documents/GitHub/Parquet-Processor/.github/scripts/test_parquet_processor.py", line 298, in process_url_batch
    driver = setup_driver()
  File "/Users/jt/Documents/GitHub/Parquet-Processor/.github/scripts/test_parquet_processor.py", line 72, in setup_driver
    driver = webdriver.Chrome(options=chrome_options)
  File "/usr/local/lib/python3.10/site-packages/selenium/webdriver/chrome/webdriver.py", line 45, in __init__
    super().__init__(
  File "/usr/local/lib/python3.10/site-packages/selenium/webdriver/chromium/webdriver.py", line 50, in __init__
    if finder.get_browser_path():
  File "/usr/local/lib/python3.10/site-packages/selenium/webdriver/common/driver_finder.py", line 47, in get_browser_path
    return self._binary_paths()["browser_path"]
  File "/usr/local/lib/python3.10/site-packages/selenium/webdriver/common/driver_finder.py", line 78, in _binary_paths
    raise NoSuchDriverException(msg) from err
selenium.common.exceptions.NoSuchDriverException: Message: Unable to obtain driver for chrome; For documentation on this error, please visit: https://www.selenium.dev/documentation/webdriver/troubleshooting/errors/driver_location

2025-01-31 02:23:07,503 - INFO - Retrying https://www.morphosource.org/concern/media/000705559?locale=en after error...
2025-01-31 02:23:08,507 - INFO - Setting up new Chrome driver
2025-01-31 02:23:08,654 - ERROR - Error on attempt 2 for https://www.morphosource.org/concern/media/000705559?locale=en: Message: Unable to obtain driver for chrome; For documentation on this error, please visit: https://www.selenium.dev/documentation/webdriver/troubleshooting/errors/driver_location
Traceback (most recent call last):
  File "/usr/local/lib/python3.10/site-packages/selenium/webdriver/common/driver_finder.py", line 67, in _binary_paths
    output = SeleniumManager().binary_paths(self._to_args())
  File "/usr/local/lib/python3.10/site-packages/selenium/webdriver/common/selenium_manager.py", line 55, in binary_paths
    return self._run(args)
  File "/usr/local/lib/python3.10/site-packages/selenium/webdriver/common/selenium_manager.py", line 129, in _run
    raise WebDriverException(
selenium.common.exceptions.WebDriverException: Message: Unsuccessful command executed: /usr/local/lib/python3.10/site-packages/selenium/webdriver/common/linux/selenium-manager --browser chrome --browser-path /usr/bin/google-chrome --language-binding python --output json; code: 65
{'code': 65, 'message': 'Browser path does not exist: /usr/bin/google-chrome', 'driver_path': '', 'browser_path': ''}



The above exception was the direct cause of the following exception:

Traceback (most recent call last):
  File "/Users/jt/Documents/GitHub/Parquet-Processor/.github/scripts/test_parquet_processor.py", line 298, in process_url_batch
    driver = setup_driver()
  File "/Users/jt/Documents/GitHub/Parquet-Processor/.github/scripts/test_parquet_processor.py", line 72, in setup_driver
    driver = webdriver.Chrome(options=chrome_options)
  File "/usr/local/lib/python3.10/site-packages/selenium/webdriver/chrome/webdriver.py", line 45, in __init__
    super().__init__(
  File "/usr/local/lib/python3.10/site-packages/selenium/webdriver/chromium/webdriver.py", line 50, in __init__
    if finder.get_browser_path():
  File "/usr/local/lib/python3.10/site-packages/selenium/webdriver/common/driver_finder.py", line 47, in get_browser_path
    return self._binary_paths()["browser_path"]
  File "/usr/local/lib/python3.10/site-packages/selenium/webdriver/common/driver_finder.py", line 78, in _binary_paths
    raise NoSuchDriverException(msg) from err
selenium.common.exceptions.NoSuchDriverException: Message: Unable to obtain driver for chrome; For documentation on this error, please visit: https://www.selenium.dev/documentation/webdriver/troubleshooting/errors/driver_location

2025-01-31 02:23:08,658 - INFO - Processed 0 records in this batch
